<?xml version="1.0" encoding="utf-8" ?>
<robot name="panda_hebi">
	<!-- Panda link 0 -->
	<link name="panda_link0">
		<visual>
			<geometry>
				<mesh filename="franka/Franka_Link0_assy OBJ/Franka_Link0_assy.obj" />
			</geometry>
		</visual>
		<inertial>
			<origin rpy="0 0 0" xyz="0 0 0" />
			<mass value="2.9411" />
			<inertia ixx="0.00315" ixy="0.0" ixz="0.0" iyy="0.00388" iyz="0.0" izz="0.004285" />
		</inertial>
	</link>
	<!-- Joint 1 from link 0 to 1 -->
	<joint name="panda_joint1" type="revolute">
		<origin rpy="0 0 0" xyz="0 0 0.333" />
		<parent link="panda_link0" />
		<child link="panda_link1" />
		<axis xyz="0 0 1" />
		<limit effort="87" lower="-2.8973" upper="2.8973" velocity="2.1750" />
		<dynamics damping="1.0" />
	</joint>
	<!-- Panda link 1 -->
	<link name="panda_link1">
		<visual>
			<geometry>
				<mesh filename="franka/Franka_Link1_assy OBJ/Franka_Link1_assy.obj" />
			</geometry>
		</visual>
		<inertial>
			<origin rpy="0 0 0" xyz="0.003875 0.002081 -0.04762" />
			<mass value="4.970684" />
			<inertia ixx="0.70337" ixy="0" ixz="0" iyy="0.70661" iyz="0" izz="0.0091170" />
		</inertial>
	</link>
	<!-- Joint 2 from link 1 to 2 -->
	<joint name="panda_joint2" type="revolute">
		<origin rpy="-1.57079632679 0 0" xyz="0 0 0" />
		<parent link="panda_link1" />
		<child link="panda_link2" />
		<axis xyz="0 0 1" />
		<limit effort="87" lower="-1.7628" upper="1.7628" velocity="2.1750" />
		<dynamics damping="1.0" />
	</joint>
	<!-- Panda link 2 -->
	<link name="panda_link2">
		<visual>
			<geometry>
				<mesh filename="franka/Franka_Link2_assy OBJ/Franka_Link2_assy.obj" />
				<!--<mesh filename="assets/panda/link2.stl" />-->
			</geometry>
		</visual>
		<inertial>
			<origin rpy="0 0 0" xyz="-0.003141 -0.02872 0.003495" />
			<mass value="0.646926" />
			<inertia ixx="0.0079620" ixy="0.0" ixz="0.0" iyy="0.02811" iyz="0.0" izz="0.025995" />
		</inertial>
	</link>
	<!-- Joint 3 from link 2 to 3 -->
	<joint name="panda_joint3" type="revolute">
		<origin rpy="1.57079632679 0 0" xyz="0 -0.316 0" />
		<parent link="panda_link2" />
		<child link="panda_link3" />
		<axis xyz="0 0 1" />
		<limit effort="87" lower="-2.8973" upper="2.8973" velocity="2.1750" />
		<dynamics damping="1.0" />
	</joint>
	<!-- Panda link 3 -->
	<link name="panda_link3">
		<visual>
			<geometry>
				<mesh filename="franka/Franka_Link3_assy OBJ/Franka_Link3_assy.obj" />
				<!--<mesh filename="assets/panda/link3.stl" />-->
			</geometry>
		</visual>
		<inertial>
			<origin rpy="0 0 0" xyz="2.7518e-2 3.9252e-2 -6.6502e-2" />
			<mass value="3.228604" />
			<inertia ixx="0.037242" ixy="0.0" ixz="0.0" iyy="0.036155" iyz="0.0" izz="0.01083" />
		</inertial>
	</link>
	<!-- Joint 4 from link 3 to 4 -->
	<joint name="panda_joint4" type="revolute">
		<origin rpy="1.57079632679 0 0" xyz="0.0825 0 0" />
		<parent link="panda_link3" />
		<child link="panda_link4" />
		<axis xyz="0 0 1" />
		<limit effort="87" lower="-3.0718" upper="-0.0698" velocity="2.1750" />
		<dynamics damping="1.0" />
	</joint>
	<!-- Panda link 4 -->
	<link name="panda_link4">
		<visual>
			<geometry>
				<mesh filename="franka/Franka_Link4_assy OBJ/Franka_Link4_assy.obj" />
				<!--<mesh filename="assets/panda/link4.stl" />-->
			</geometry>
		</visual>
		<inertial>
			<origin rpy="0 0 0" xyz="-5.317e-2 1.04419e-1 2.7454e-2" />
			<mass value="3.587895" />
			<inertia ixx="2.5853e-2" ixy="0.0" ixz="0.0" iyy="1.9552e-2" iyz="0.0" izz="8.627e-3" />
		</inertial>
	</link>
	<!-- Joint 5 from link 4 to 5 -->
	<joint name="panda_joint5" type="revolute">
		<origin rpy="-1.57079632679 0 0" xyz="-0.0825 0.384 0" />
		<parent link="panda_link4" />
		<child link="panda_link5" />
		<axis xyz="0 0 1" />
		<limit effort="12" lower="-2.8973" upper="2.8973" velocity="2.6100" />
		<dynamics damping="1.0" />
	</joint>
	<!-- Panda link 5 -->
	<link name="panda_link5">
		<visual>
			<geometry>
				<mesh filename="franka/Franka_Link5_assy OBJ/Franka_Link5_assy.obj" />
				<!--<mesh filename="assets/panda/link5.stl" />-->
			</geometry>
		</visual>
		<inertial>
			<origin rpy="0 0 0" xyz="-1.1953e-2 4.1065e-2 -3.8437e-2" />
			<mass value="1.225946" />
			<inertia ixx="3.5549e-2" ixy="0.0" ixz="0.0" iyy="2.9474e-2" iyz="0.0" izz="8.627e-3" />
		</inertial>
	</link>
	<!-- Joint 6 from link 5 to 6 -->
	<joint name="panda_joint6" type="revolute">
		<origin rpy="1.57079632679 0 0" xyz="0 0 0" />
		<parent link="panda_link5" />
		<child link="panda_link6" />
		<axis xyz="0 0 1" />
		<limit effort="12" lower="-0.0175" upper="3.7525" velocity="2.6100" />
		<dynamics damping="1.0" />
	</joint>
	<!-- Panda link 6 -->
	<link name="panda_link6">
		<visual>
			<geometry>
				<mesh filename="franka/Franka_Link6_assy OBJ/Franka_Link6_assy.obj" />
				<!--<mesh filename="assets/panda/link6.stl" />-->
			</geometry>
		</visual>
		<inertial>
			<origin rpy="0 0 0" xyz="6.0149e-2 -1.4117e-2 -1.0517e-2" />
			<mass value="1.666555" />
			<inertia ixx="1.964e-3" ixy="0.0" ixz="0.0" iyy="4.354e-3" iyz="0.0" izz="5.433e-3" />
		</inertial>
	</link>
	<!-- Joint 7 from link 6 to 7 -->
	<joint name="panda_joint7" type="revolute">
		<origin rpy="1.57079632679 0 0" xyz="0.088 0 0" />
		<parent link="panda_link6" />
		<child link="panda_link7" />
		<axis xyz="0 0 1" />
		<limit effort="12" lower="-2.8973" upper="2.8973" velocity="2.6100" />
		<dynamics damping="1.0" />
	</joint>
	<!-- Panda link 7 -->
	<link name="panda_link7">
		<visual>
			<origin rpy="0 0 0" xyz="0 0 0" />
			<geometry>
				<mesh filename="franka/Franka_Link7_assy OBJ/Franka_Link7_assy.obj" />
			</geometry>
		</visual>
		<inertial>
			<origin rpy="0 0 0" xyz="1.0517e-2 -4.252e-3 6.1597e-2" />
			<mass value="7.35522e-01" />
			<inertia ixx="1.2516e-2" ixy="0.0" ixz="0.0" iyy="1.0027e-2" iyz="0.0" izz="4.815e-3" />
		</inertial>
	</link>
	<!-- Fixed joint from link 7 to hand -->
	<joint name="panda_joint8" type="fixed">
		<origin rpy="0 0 0" xyz="0 0 0.107" />
		<parent link="panda_link7" />
		<child link="hebi" />
		<axis xyz="0 0 1" />
	</joint>
	<!--Hebi-->
	<link name="hebi">
		<visual>
			<origin rpy="0 0 0" xyz="0 0 0" />
			<geometry>
				<mesh filename="../hebi/Hebi_X_ATI_gamma.obj" />
			</geometry>
		</visual>
		<inertial>
			<origin rpy="0 0 0" xyz="-0.01 0 0.03" />
			<mass value="0.73"/>
			<inertia ixx="0.001" ixy="0.0" ixz="0.0" iyy="0.0025" iyz="0.0" izz="0.0017" />
		</inertial>
	</link>
	<!-- Revolute joint from Hebi to nut -->
	<joint name="panda_joint9" type="revolute">
		<origin rpy="0 0 -2.3562" xyz="0 0 0" />
		<parent link="hebi" />
		<child link="nut" />
		<axis xyz="0 0 1" />
	</joint>
	<!--Nut-->
	<link name="nut">
		<visual>
			<origin rpy="0 0 0" xyz="0 0 0.09615" />
			<geometry>
				<mesh filename="../boltnut/M48_P5_nut.obj" />
			</geometry>
		</visual>
		<collision>
			<origin rpy="0 0 0" xyz="0 0 0.09615" />
			<geometry>
				<mesh filename="../boltnut/M48_P5_nut.obj" />
			</geometry>
		</collision>
		<inertial>
			<origin rpy="0 0 0" xyz="0 0 0" />
			<mass value="0.383"/>
      		<inertia ixx="0.001915" ixy="0.0" ixz="0.0" iyy="0.0047875" iyz="0.0" izz="0.0032555" />
		</inertial>
	</link>
</robot>
